from .custom_exception import DataError